Workbook

Sheet Version Log
B5: Version | C5: Date Updated
B6: 1 | C6: 2025.09.01
B7: 2 | C7: 2025.10.20

Sheet Solar Data v1
A1: ACCOUNT_NO | B1: TRANSFORMER_CODE | C1: POLE | D1: CAPACITY | E1: INV_CAPACITY | F1: NET_CON_START_DATE | G1: Tr cap | K1: tx_id | L1: kVA_rating
A2: 0200162809 | B2: AZ0102 | C2: PN69C | D2: 16.5 | E2: 15 | F2: 44097.661 | G2: =VLOOKUP(B2,'Transformer Data'!B:C,2,FALSE) -> 250 | K2: AZ9612 | L2: 160
A3: 0200251711 | B3: AZ0653 | C3: PW28/6 | D3: 33.6 | E3: 30 | F3: 45530.527 | G3: =VLOOKUP(B3,'Transformer Data'!B:C,2,FALSE) -> 160 | K3: AZ0028 | L3: 160
A4: 0200323002 | B4: AZ0106 | C4: PW70/24/12 | D4: 4.72 | E4: 5 | F4: 45517.468 | G4: =VLOOKUP(B4,'Transformer Data'!B:C,2,FALSE) -> 160 | K4: AZ0708 | L4: 160
A5: 0200330504 | B5: AZ0106 | C5: PW70/24/4 | D5: 6.05 | E5: 5 | F5: 45819.759 | G5: =VLOOKUP(B5,'Transformer Data'!B:C,2,FALSE) -> 160 | K5: AZ0076 | L5: 100
A6: 0200337005 | B6: AZ0106 | C6: PW70/24/10F | D6: 6.05 | E6: 5 | F6: 45881.775 | G6: =VLOOKUP(B6,'Transformer Data'!B:C,2,FALSE) -> 160 | K6: AZ0091 | L6: 160
A7: 0200359302 | B7: AZ0652 | C7: PW6/13-1/1 | D7: 10.87 | E7: 12.5 | F7: 44189.622 | G7: =VLOOKUP(B7,'Transformer Data'!B:C,2,FALSE) -> 630 | K7: AZ0733 | L7: 160
A8: 0200361304 | B8: AZ0689 | C8: PW13 | D8: 42.24 | E8: 40 | F8: 43251.561 | G8: =VLOOKUP(B8,'Transformer Data'!B:C,2,FALSE) -> 160 | K8: AZ0061 | L8: 160
A9: 0200396702 | B9: AZ0676 | C9: PN16Y/D | D9: 3.41 | E9: 3 | F9: 44282.402 | G9: =VLOOKUP(B9,'Transformer Data'!B:C,2,FALSE) -> 160 | K9: AZ0067 | L9: 100
A10: 0200399001 | B10: AZ0676 | C10: PN16Y/F | D10: 8.25 | E10: 8 | F10: 43154.739 | G10: =VLOOKUP(B10,'Transformer Data'!B:C,2,FALSE) -> 160 | K10: AZ0074 | L10: 100
A11: 0200399903 | B11: AZ0676 | C11: PN16Y/H | D11: 5.45 | E11: 5 | F11: 45369.623 | G11: =VLOOKUP(B11,'Transformer Data'!B:C,2,FALSE) -> 160 | K11: AZ0077 | L11: 250
A12: 0200402708 | B12: AZ0676 | C12: PN16Y/L/A | D12: 2.2 | E12: 2 | F12: 45369.681 | G12: =VLOOKUP(B12,'Transformer Data'!B:C,2,FALSE) -> 160 | K12: AZ0089 | L12: 160
A13: 0200409902 | B13: AZ0676 | C13: PN16X/B | D13: 40.12 | E13: 40 | F13: 45772.759 | G13: =VLOOKUP(B13,'Transformer Data'!B:C,2,FALSE) -> 160 | K13: AZ0090 | L13: 160
... A300: 0200986302 | B300: AZ0097 | C300: DW86F1 | D300: 5.46 | E300: 5 | F300: 44641.761 | G300: =VLOOKUP(B300,'Transformer Data'!B:C,2,FALSE) -> 160 | K300: AZ9848 | L300: 100
A301: 0200989305 | B301: AZ0096 | C301: DW87/1-1 | D301: 6.16 | E301: 5 | F301: 45467.507 | G301: =VLOOKUP(B301,'Transformer Data'!B:C,2,FALSE) -> 160 | K301: AZ9842 | L301: null
A302: 0200704405 | B302: AZ0092 | C302: DP64/12 | D302: 6.72 | E302: 5 | F302: 45649.758 | G302: =VLOOKUP(B302,'Transformer Data'!B:C,2,FALSE) -> 100 | K302: AZ9844 | L302: 160
A303: 0200806804 | B303: AZ0090 | C303: DP68 | D303: 5.5 | E303: 5 | F303: 45236.484 | G303: =VLOOKUP(B303,'Transformer Data'!B:C,2,FALSE) -> 160 | K303: AZ0702 | L303: 160
A304: 0200807002 | B304: AZ0090 | C304: DP68//1 | D304: 4.16 | E304: 4 | F304: 43063.725 | G304: =VLOOKUP(B304,'Transformer Data'!B:C,2,FALSE) -> 160 | K304: AZ0360 | L304: 160
A305: 0200808003 | B305: AZ0090 | C305: DP64-1C | D305: 6.05 | E305: 5 | F305: 45850.679 | G305: =VLOOKUP(B305,'Transformer Data'!B:C,2,FALSE) -> 160 | K305: AZ9813 | L305: 400
A306: 0200808311 | B306: AZ0090 | C306: DP64-1B/A | D306: 2 | E306: 2 | F306: 43325.725 | G306: =VLOOKUP(B306,'Transformer Data'!B:C,2,FALSE) -> 160 | K306: AZ9843 | L306: 100
A307: 0200810808 | B307: AZ0724 | C307: DW105 | D307: 4.6 | E307: 4.6 | F307: 42686 | G307: =VLOOKUP(B307,'Transformer Data'!B:C,2,FALSE) -> 100 | K307: AZ0014 | L307: 160
A308: 0200901206 | B308: AZ0097 | C308: DW90A/B | D308: 6.05 | E308: 5 | F308: 45850.678 | G308: =VLOOKUP(B308,'Transformer Data'!B:C,2,FALSE) -> 160 | K308: AZ9822 | L308: 160
A309: 0200901503 | B309: AZ0097 | C309: DW89 | D309: 6.15 | E309: 5 | F309: 45765.745 | G309: =VLOOKUP(B309,'Transformer Data'!B:C,2,FALSE) -> 160 | K309: AZ0021 | L309: 160
A310: 0200901602 | B310: AZ0097 | C310: DW89A | D310: 6.15 | E310: 5 | F310: 45728.731 | G310: =VLOOKUP(B310,'Transformer Data'!B:C,2,FALSE) -> 160 | K310: AZ9829 | L310: 160
A311: 0200901811 | B311: AZ0097 | C311: DW89 | D311: 15 | E311: 15 | F311: 44614.775 | G311: =VLOOKUP(B311,'Transformer Data'!B:C,2,FALSE) -> 160 | K311: AZ0023 | L311: 250
A312: 0200902405 | B312: AZ0097 | C312: DW89 | D312: 19.98 | E312: 20 | F312: 44614.821 | G312: =VLOOKUP(B312,'Transformer Data'!B:C,2,FALSE) -> 160 | K312: AZ9834 | L312: 160
A313: 0200906002 | B313: AZ0096 | C313: DW87/17 | D313: 5.31 | E313: 5 | F313: 45822.622 | G313: =VLOOKUP(B313,'Transformer Data'!B:C,2,FALSE) -> 160 | K313: AZ9826 | L313: 250
... A577: 0202830309 | B577: AZ0703 | C577: DH16 | D577: 5.6 | E577: 5 | F577: 45393.454 | G577: =VLOOKUP(B577,'Transformer Data'!B:C,2,FALSE) -> 160 | K577: BZ9640 | L577: 250
A578: 0202833301 | B578: AZ0730 | C578: DH13 | D578: 5.5 | E578: 5 | F578: 45037.8 | G578: =VLOOKUP(B578,'Transformer Data'!B:C,2,FALSE) -> 160 | K578: AZ9063 | L578: null
A579: 0202836007 | B579: AZ0059 | C579: DK52B | D579: 5.6 | E579: 5 | F579: 44516.763 | G579: =VLOOKUP(B579,'Transformer Data'!B:C,2,FALSE) -> 160 | K579: AZ9054 | L579: 160
A580: 0202839901 | B580: AZ0059 | C580: DK56/1A | D580: 9.6 | E580: 10 | F580: 44123.447 | G580: =VLOOKUP(B580,'Transformer Data'!B:C,2,FALSE) -> 160 | K580: AZ0670 | L580: 160
A581: 0202840605 | B581: AZ0059 | C581: DK55-1/5 | D581: 5.9 | E581: 6 | F581: 45621.729 | G581: =VLOOKUP(B581,'Transformer Data'!B:C,2,FALSE) -> 160 | K581: AZ9762 | L581: 400
A582: 0202855906 | B582: AZ0131 | C582: DK37ZF8 | D582: 5.06 | E582: 5 | F582: 44490.777 | G582: =VLOOKUP(B582,'Transformer Data'!B:C,2,FALSE) -> 160 | K582: AZ9068 | L582: 160
A583: 0202856302 | B583: AZ0131 | C583: DK37ZF7B | D583: 5.85 | E583: 6 | F583: 43487.518 | G583: =VLOOKUP(B583,'Transformer Data'!B:C,2,FALSE) -> 160 | K583: AZ9906 | L583: 100
A584: 0202858007 | B584: AZ0060 | C584: DK59-1 | D584: 5.8 | E584: 5 | F584: 45485.754 | G584: =VLOOKUP(B584,'Transformer Data'!B:C,2,FALSE) -> 160 | K584: AZ9039 | L584: 400
A585: 0202859503 | B585: AZ0060 | C585: DK60C | D585: 5.5 | E585: 5 | F585: 45348.398 | G585: =VLOOKUP(B585,'Transformer Data'!B:C,2,FALSE) -> 160 | K585: AZ9066 | L585: 250
A586: 0202859602 | B586: AZ0060 | C586: DK60C | D586: 5.52 | E586: 5 | F586: 45348.396 | G586: =VLOOKUP(B586,'Transformer Data'!B:C,2,FALSE) -> 160 | K586: AZ9065 | L586: 100
A587: 0202860801 | B587: AZ0060 | C587: DK62//3 | D587: 5.1 | E587: 6 | F587: 42940.659 | G587: =VLOOKUP(B587,'Transformer Data'!B:C,2,FALSE) -> 160 | K587: AZ9070 | L587: 400
A588: 0202861208 | B588: AZ0060 | C588: DK62//5 | D588: 3 | E588: 3 | F588: 45391.708 | G588: =VLOOKUP(B588,'Transformer Data'!B:C,2,FALSE) -> 160 | K588: AZ0655 | L588: 100
A589: 0202861604 | B589: AZ0060 | C589: DK62//5 | D589: 4.55 | E589: 6 | F589: 43651.538 | G589: =VLOOKUP(B589,'Transformer Data'!B:C,2,FALSE) -> 160 | K589: AZ9003 | L589: 100
...

Sheet Pivot Table V2
A3: Row Labels | B3: Sum of INV_CAPACITY
A4: AW9062 | B4: 250
A5: PW47/21 | B5: 250
A6: Grand Total | B6: 250
A13: 2
B17: AZ

Sheet Solar Data V2
A1: ACCOUNT_NO | B1: TRANSFORMER_CODE | C1: POLE | D1: CAPACITY | E1: INV_CAPACITY | F1: NET_CON_START_DATE
A2: 0200162809 | B2: AZ0102 | C2: PN69C | D2: 16.5 | E2: 15 | F2: 44097.661
A3: 0200251711 | B3: AZ0653 | C3: PW28/6 | D3: 33.6 | E3: 30 | F3: 45530.527
A4: 0200323002 | B4: AZ0106 | C4: PW70/24/12 | D4: 4.72 | E4: 5 | F4: 45517.468
A5: 0200330504 | B5: AZ0106 | C5: PW70/24/4 | D5: 6.05 | E5: 5 | F5: 45819.759
A6: 0200337005 | B6: AZ0106 | C6: PW70/24/10F | D6: 6.05 | E6: 5 | F6: 45881.775
A7: 0200359302 | B7: AZ0652 | C7: PW6/13-1/1 | D7: 10.87 | E7: 12.5 | F7: 44189.622
A8: 0200361304 | B8: AZ0689 | C8: PW13 | D8: 42.24 | E8: 40 | F8: 43251.561
A9: 0200396702 | B9: AZ0676 | C9: PN16Y/D | D9: 3.41 | E9: 3 | F9: 44282.402
A10: 0200399001 | B10: AZ0676 | C10: PN16Y/F | D10: 8.25 | E10: 8 | F10: 43154.739
A11: 0200399903 | B11: AZ0676 | C11: PN16Y/H | D11: 5.45 | E11: 5 | F11: 45369.623
A12: 0200402708 | B12: AZ0676 | C12: PN16Y/L/A | D12: 2.2 | E12: 2 | F12: 45369.681
A13: 0200409902 | B13: AZ0676 | C13: PN16X/B | D13: 40.12 | E13: 40 | F13: 45772.759
... A4745: 0211602303 | B4745: BZ0147 | C4745: AR32E4 | D4745: 7.44 | E4745: 5 | F4745: 45854.774

Sheet Transformer Data
A1: Index | B1: tx_id | C1: kVA_rating
A2: 1 | B2: AZ9612 | C2: 160
A3: 2 | B3: AZ0028 | C3: 160
A4: 3 | B4: AZ0708 | C4: 160
A5: 4 | B5: AZ0076 | C5: 100
A6: 5 | B6: AZ0091 | C6: 160
A7: 6 | B7: AZ0733 | C7: 160
A8: 7 | B8: AZ0061 | C8: 160
A9: 8 | B9: AZ0067 | C9: 100
A10: 9 | B10: AZ0074 | C10: 100
A11: 10 | B11: AZ0077 | C11: 250
A12: 11 | B12: AZ0089 | C12: 160
A13: 12 | B13: AZ0090 | C13: 160
... A300: 299 | B300: AZ9848 | C300: 100
A301: 300 | B301: AZ9842 | C301: null
A302: 301 | B302: AZ9844 | C302: 160
A303: 302 | B303: AZ0702 | C303: 160
A304: 303 | B304: AZ0360 | C304: 160
A305: 304 | B305: AZ9813 | C305: 400
A306: 305 | B306: AZ9843 | C306: 100
A307: 306 | B307: AZ0014 | C307: 160
A308: 307 | B308: AZ9822 | C308: 160
A309: 308 | B309: AZ0021 | C309: 160
A310: 309 | B310: AZ9829 | C310: 160
A311: 310 | B311: AZ0023 | C311: 250
A312: 311 | B312: AZ9834 | C312: 160
A313: 312 | B313: AZ9826 | C313: 250
... A577: 576 | B577: BZ9640 | C577: 250
A578: 577 | B578: AZ9063 | C578: null
A579: 578 | B579: AZ9054 | C579: 160
A580: 579 | B580: AZ0670 | C580: 160
A581: 580 | B581: AZ9762 | C581: 400
A582: 581 | B582: AZ9068 | C582: 160
A583: 582 | B583: AZ9906 | C583: 100
A584: 583 | B584: AZ9039 | C584: 400
A585: 584 | B585: AZ9066 | C585: 250
A586: 585 | B586: AZ9065 | C586: 100
A587: 586 | B587: AZ9070 | C587: 400
A588: 587 | B588: AZ0655 | C588: 100
A589: 588 | B589: AZ9003 | C589: 100
...

Sheet Pivot Table- Transformer Wise
A3: Sum of INV_CAPACITY
A4: TRANSFORMER_CODE | B4: Tr cap | C4: POLE | D4: ACCOUNT_NO | E4: Total
A5: AW9062 | B5: 1000 | C5: PW47/21 | D5: 0210821809 | E5: 250
C6: PW47/21 Total | E6: 250
B7: 1000 Total | E7: 250
A8: AW9062 Total | E8: 250
A9: AX0695 | B9: 1000 | C9: PW16/18/L/M | D9: 0208381305 | E9: 870
C10: PW16/18/L/M Total | E10: 870
B11: 1000 Total | E11: 870
A12: AX0695 Total | E12: 870
A13: AZ0001 | B13: 160 | C13: DER26F1 | D13: 0203612904 | E13: 5
C14: DER26F1 Total | E14: 5
C15: DER26F1/2/1 | D15: 0203603202 | E15: 5
C16: DER26F1/2/1 Total | E16: 5
C17: DER26F10C | D17: 0203629503 | E17: 3
C18: DER26F10C Total | E18: 3
C19: DER26F13 | D19: 0203619306 | E19: 5
C20: DER26F13 Total | E20: 5
C21: DER26F2 | D21: 0203613410 | E21: 3
C22: DER26F2 Total | E22: 3
C23: DER26F2A | D23: 0203612706 | E23: 5
C24: DER26F2A Total | E24: 5
C25: DER26F2C | D25: 0203613102 | E25: 5
C26: DER26F2C Total | E26: 5
C27: DER26F3 | D27: 0203613311 | E27: 3
C28: DER26F3 Total | E28: 3
C29: DER26F3A | D29: 0203613905 | E29: 20
C30: DER26F3A Total | E30: 20
C31: DER26F4 | D31: 0203614708 | E31: 5
C32: DER26F4 Total | E32: 5
C33: DER26F4A | D33: 0203613707 | E33: 6
C34: DER26F4A Total | E34: 6
C35: DER26F4F | D35: 0203615808 | E35: 10
C36: DER26F4F Total | E36: 10
C37: DER26F4K | D37: 0203618404 | E37: 5
C38: DER26F4K Total | E38: 5
C39: DER26F4M/A | D39: 0203619603 | E39: 5
C40: DER26F4M/A Total | E40: 5
C41: DER26F6/5 | D41: 0203622903 | E41: 5
C42: DER26F6/5 Total | E42: 5
...
